Workbook

Sheet 一覧
A1: 日付 | B1: 件数 | C1: 正味の料金 | D1: プロモーション | E1: その他 | F1: チップ | G1: 全体金額 | H1: 1件平均 | I1: 全体平均
A2: 45658 | G2: =C2+D2+E2+F2 -> 0 | H2: =C2/B2 -> #DIV/0! | I2: =G2/B2 -> #DIV/0!
A3: 45659 | G3: =C3+D3+E3+F3 -> 0 | H3: =C3/B3 -> #DIV/0! | I3: =G3/B3 -> #DIV/0!
A4: 45660 | G4: =C4+D4+E4+F4 -> 0 | H4: =C4/B4 -> #DIV/0! | I4: =G4/B4 -> #DIV/0!
A5: 45661 | G5: =C5+D5+E5+F5 -> 0 | H5: =C5/B5 -> #DIV/0! | I5: =G5/B5 -> #DIV/0!
A6: 45662 | G6: =C6+D6+E6+F6 -> 0 | H6: =C6/B6 -> #DIV/0! | I6: =G6/B6 -> #DIV/0!
A7: 45663 | G7: =C7+D7+E7+F7 -> 0 | H7: =C7/B7 -> #DIV/0! | I7: =G7/B7 -> #DIV/0!
A8: 45664 | G8: =C8+D8+E8+F8 -> 0 | H8: =C8/B8 -> #DIV/0! | I8: =G8/B8 -> #DIV/0!
A9: 45665 | G9: =C9+D9+E9+F9 -> 0 | H9: =C9/B9 -> #DIV/0! | I9: =G9/B9 -> #DIV/0!
A10: 45666 | G10: =C10+D10+E10+F10 -> 0 | H10: =C10/B10 -> #DIV/0! | I10: =G10/B10 -> #DIV/0!
A11: 45667 | G11: =C11+D11+E11+F11 -> 0 | H11: =C11/B11 -> #DIV/0! | I11: =G11/B11 -> #DIV/0!
A12: 45668 | G12: =C12+D12+E12+F12 -> 0 | H12: =C12/B12 -> #DIV/0! | I12: =G12/B12 -> #DIV/0!
A13: 45669 | G13: =C13+D13+E13+F13 -> 0 | H13: =C13/B13 -> #DIV/0! | I13: =G13/B13 -> #DIV/0!
... A73: 45729 | G73: =C73+D73+E73+F73 -> 0 | H73: =C73/B73 -> #DIV/0! | I73: =G73/B73 -> #DIV/0!
A74: 45730 | B74: 9 | C74: 4352 | G74: =C74+D74+E74+F74 -> 4352 | H74: =C74/B74 -> 483.55556 | I74: =G74/B74 -> 483.55556
A75: 45731 | B75: 7 | C75: 3209 | G75: =C75+D75+E75+F75 -> 3209 | H75: =C75/B75 -> 458.42857 | I75: =G75/B75 -> 458.42857
A76: 45732 | G76: =C76+D76+E76+F76 -> 0 | H76: =C76/B76 -> #DIV/0! | I76: =G76/B76 -> #DIV/0!
A77: 45733 | B77: 5 | C77: 2137 | F77: 69 | G77: =C77+D77+E77+F77 -> 2206 | H77: =C77/B77 -> 427.4 | I77: =G77/B77 -> 441.2
A78: 45734 | B78: 26 | C78: 12760 | F78: 100 | G78: =C78+D78+E78+F78 -> 12860 | H78: =C78/B78 -> 490.76923 | I78: =G78/B78 -> 494.61538
A79: 45735 | B79: 12 | C79: 4562 | G79: =C79+D79+E79+F79 -> 4562 | H79: =C79/B79 -> 380.16667 | I79: =G79/B79 -> 380.16667
A80: 45736 | B80: 24 | C80: 10153 | G80: =C80+D80+E80+F80 -> 10153 | H80: =C80/B80 -> 423.04167 | I80: =G80/B80 -> 423.04167
A81: 45737 | B81: 2 | C81: 715 | G81: =C81+D81+E81+F81 -> 715 | H81: =C81/B81 -> 357.5 | I81: =G81/B81 -> 357.5
A82: 45738 | B82: 11 | C82: 5098 | G82: =C82+D82+E82+F82 -> 5098 | H82: =C82/B82 -> 463.45455 | I82: =G82/B82 -> 463.45455
A83: 45739 | B83: 10 | C83: 3670 | G83: =C83+D83+E83+F83 -> 3670 | H83: =C83/B83 -> 367 | I83: =G83/B83 -> 367
A84: 45740 | B84: 10 | C84: 3787 | D84: 750 | F84: 192 | G84: =C84+D84+E84+F84 -> 4729 | H84: =C84/B84 -> 378.7 | I84: =G84/B84 -> 472.9
A85: 45741 | B85: 15 | C85: 6955 | D85: 1125 | F85: 388 | G85: =C85+D85+E85+F85 -> 8468 | H85: =C85/B85 -> 463.66667 | I85: =G85/B85 -> 564.53333
A86: 45742 | G86: =C86+D86+E86+F86 -> 0 | H86: =C86/B86 -> #DIV/0! | I86: =G86/B86 -> #DIV/0!
A87: 45743 | B87: 21 | C87: 10466 | G87: =C87+D87+E87+F87 -> 10466 | H87: =C87/B87 -> 498.38095 | I87: =G87/B87 -> 498.38095
A88: 45744 | B88: 13 | C88: 5812 | G88: =C88+D88+E88+F88 -> 5812 | H88: =C88/B88 -> 447.07692 | I88: =G88/B88 -> 447.07692
A89: 45745 | B89: 3 | C89: 1332 | G89: =C89+D89+E89+F89 -> 1332 | H89: =C89/B89 -> 444 | I89: =G89/B89 -> 444
A90: 45746 | B90: 1 | C90: 922 | G90: =C90+D90+E90+F90 -> 922 | H90: =C90/B90 -> 922 | I90: =G90/B90 -> 922
A91: 45747 | G91: =C91+D91+E91+F91 -> 0 | H91: =C91/B91 -> #DIV/0! | I91: =G91/B91 -> #DIV/0!
A92: 45748 | G92: =C92+D92+E92+F92 -> 0 | H92: =C92/B92 -> #DIV/0! | I92: =G92/B92 -> #DIV/0!
A93: 45749 | B93: 15 | C93: 5439 | G93: =C93+D93+E93+F93 -> 5439 | H93: =C93/B93 -> 362.6 | I93: =G93/B93 -> 362.6
A94: 45750 | B94: 10 | C94: 3247 | D94: 2800 | F94: 289 | G94: =C94+D94+E94+F94 -> 6336 | H94: =C94/B94 -> 324.7 | I94: =G94/B94 -> 633.6
A95: 45751 | B95: 32 | C95: 13419 | D95: 3000 | G95: =C95+D95+E95+F95 -> 16419 | H95: =C95/B95 -> 419.34375 | I95: =G95/B95 -> 513.09375
A96: 45752 | B96: 21 | C96: 8298 | D96: 1500 | F96: 388 | G96: =C96+D96+E96+F96 -> 10186 | H96: =C96/B96 -> 395.14286 | I96: =G96/B96 -> 485.04762
A97: 45753 | B97: 11 | C97: 5195 | F97: 240 | G97: =C97+D97+E97+F97 -> 5435 | H97: =C97/B97 -> 472.27273 | I97: =G97/B97 -> 494.09091
A98: 45754 | B98: 13 | C98: 5244 | G98: =C98+D98+E98+F98 -> 5244 | H98: =C98/B98 -> 403.38462 | I98: =G98/B98 -> 403.38462
A99: 45755 | G99: =C99+D99+E99+F99 -> 0 | H99: =C99/B99 -> #DIV/0! | I99: =G99/B99 -> #DIV/0!
...

Sheet 月ごと
A1: 年 | B1: 月 | C1: 日数 | D1: 件数 | E1: 正味金額 | F1: 全体金額 | G1: 正味平均 | H1: 正味中央値 | I1: 全体平均 | J1: 全体中央値
A2: 2025 | B2: 1 | C2: {=_xlfn.LET(_xlpm.y,$A2,_xlpm.m,$B2, _xlpm.d,一覧!$A$2:$A$99999, _xlpm.net,一覧!$C$2:$C$99999, IFERROR(ROWS(_xlfn._xlws.FILTER(_xlpm.d,(YEAR(_xlpm.d)=_xlpm.y)*(MONTH(_xlpm.d)=_xlpm.m)*(_xlpm.net<>""))),0))} -> 0 | D2: {=_xlfn.LET(_xlpm.y,$A2,_xlpm.m,$B2, _xlpm.d,一覧!$A$2:$A$99999, _xlpm.cnt,一覧!$B$2:$B$99999, _xlpm.a,_xlfn._xlws.FILTER(_xlpm.cnt,(YEAR(_xlpm.d)=_xlpm.y)*(MONTH(_xlpm.d)=_xlpm.m)), IFERROR(SUM(_xlpm.a),0))} -> 0 | E2: {=_xlfn.LET(_xlpm.y,$A2,_xlpm.m,$B2, _xlpm.d,一覧!$A$2:$A$99999, _xlpm.net,一覧!$C$2:$C$99999, _xlpm.a,_xlfn._xlws.FILTER(_xlpm.net,(YEAR(_xlpm.d)=_xlpm.y)*(MONTH(_xlpm.d)=_xlpm.m)), IFERROR(SUM(_xlpm.a),0))} -> 0 | F2: {=_xlfn.LET(_xlpm.y,$A2,_xlpm.m,$B2, _xlpm.d,一覧!$A$2:$A$99999, _xlpm.net,一覧!$G$2:$G$99999, _xlpm.a,_xlfn._xlws.FILTER(_xlpm.net,(YEAR(_xlpm.d)=_xlpm.y)*(MONTH(_xlpm.d)=_xlpm.m)), IFERROR(SUM(_xlpm.a),0))} -> 0 | G2: {=_xlfn.LET(_xlpm.y,$A2,_xlpm.m,$B2, _xlpm.d,一覧!$A$2:$A$99999, _xlpm.cnt,一覧!$B$2:$B$99999, _xlpm.net,一覧!$C$2:$C$99999, _xlpm.c,_xlfn._xlws.FILTER(_xlpm.cnt,(YEAR(_xlpm.d)=_xlpm.y)*(MONTH(_xlpm.d)=_xlpm.m)), _xlpm.n,_xlfn._xlws.FILTER(_xlpm.net,(YEAR(_xlpm.d)=_xlpm.y)*(MONTH(_xlpm.d)=_xlpm.m)), IFERROR(SUM(_xlpm.n)/SUM(_xlpm.c),""))} | H2: {=_xlfn.LET(_xlpm.y,$A2,_xlpm.m,$B2, _xlpm.d,一覧!$A$2:$A$99999, _xlpm.cnt,一覧!$B$2:$B$99999, _xlpm.net,一覧!$C$2:$C$99999, _xlpm.dc,_xlfn._xlws.FILTER(_xlpm.cnt,(YEAR(_xlpm.d)=_xlpm.y)*(MONTH(_xlpm.d)=_xlpm.m)*(_xlpm.cnt>0)), _xlpm.dn,_xlfn._xlws.FILTER(_xlpm.net,(YEAR(_xlpm.d)=_xlpm.y)*(MONTH(_xlpm.d)=_xlpm.m)*(_xlpm.cnt>0)), _xlpm.unit, _xlpm.dn/_xlpm.dc, IFERROR(MEDIAN(_xlpm.unit),""))} | I2: {=_xlfn.LET(_xlpm.y,$A2,_xlpm.m,$B2, _xlpm.d,一覧!$A$2:$A$99999, _xlpm.cnt,一覧!$B$2:$B$99999, _xlpm.net,一覧!$G$2:$G$99999, _xlpm.c,_xlfn._xlws.FILTER(_xlpm.cnt,(YEAR(_xlpm.d)=_xlpm.y)*(MONTH(_xlpm.d)=_xlpm.m)), _xlpm.n,_xlfn._xlws.FILTER(_xlpm.net,(YEAR(_xlpm.d)=_xlpm.y)*(MONTH(_xlpm.d)=_xlpm.m)), IFERROR(SUM(_xlpm.n)/SUM(_xlpm.c),""))} | J2: {=_xlfn.LET(_xlpm.y,$A2,_xlpm.m,$B2, _xlpm.d,一覧!$A$2:$A$99999, _xlpm.cnt,一覧!$B$2:$B$99999, _xlpm.net,一覧!$G$2:$G$99999, _xlpm.dc,_xlfn._xlws.FILTER(_xlpm.cnt,(YEAR(_xlpm.d)=_xlpm.y)*(MONTH(_xlpm.d)=_xlpm.m)*(_xlpm.cnt>0)), _xlpm.dn,_xlfn._xlws.FILTER(_xlpm.net,(YEAR(_xlpm.d)=_xlpm.y)*(MONTH(_xlpm.d)=_xlpm.m)*(_xlpm.cnt>0)), _xlpm.unit, _xlpm.dn/_xlpm.dc, IFERROR(MEDIAN(_xlpm.unit),""))}
A3: 2025 | B3: 2 | C3: {=_xlfn.LET(_xlpm.y,$A3,_xlpm.m,$B3, _xlpm.d,一覧!$A$2:$A$99999, _xlpm.net,一覧!$C$2:$C$99999, IFERROR(ROWS(_xlfn._xlws.FILTER(_xlpm.d,(YEAR(_xlpm.d)=_xlpm.y)*(MONTH(_xlpm.d)=_xlpm.m)*(_xlpm.net<>""))),0))} -> 0 | D3: {=_xlfn.LET(_xlpm.y,$A3,_xlpm.m,$B3, _xlpm.d,一覧!$A$2:$A$99999, _xlpm.cnt,一覧!$B$2:$B$99999, _xlpm.a,_xlfn._xlws.FILTER(_xlpm.cnt,(YEAR(_xlpm.d)=_xlpm.y)*(MONTH(_xlpm.d)=_xlpm.m)), IFERROR(SUM(_xlpm.a),0))} -> 0 | E3: {=_xlfn.LET(_xlpm.y,$A3,_xlpm.m,$B3, _xlpm.d,一覧!$A$2:$A$99999, _xlpm.net,一覧!$C$2:$C$99999, _xlpm.a,_xlfn._xlws.FILTER(_xlpm.net,(YEAR(_xlpm.d)=_xlpm.y)*(MONTH(_xlpm.d)=_xlpm.m)), IFERROR(SUM(_xlpm.a),0))} -> 0 | F3: {=_xlfn.LET(_xlpm.y,$A3,_xlpm.m,$B3, _xlpm.d,一覧!$A$2:$A$99999, _xlpm.net,一覧!$G$2:$G$99999, _xlpm.a,_xlfn._xlws.FILTER(_xlpm.net,(YEAR(_xlpm.d)=_xlpm.y)*(MONTH(_xlpm.d)=_xlpm.m)), IFERROR(SUM(_xlpm.a),0))} -> 0 | G3: {=_xlfn.LET(_xlpm.y,$A3,_xlpm.m,$B3, _xlpm.d,一覧!$A$2:$A$99999, _xlpm.cnt,一覧!$B$2:$B$99999, _xlpm.net,一覧!$C$2:$C$99999, _xlpm.c,_xlfn._xlws.FILTER(_xlpm.cnt,(YEAR(_xlpm.d)=_xlpm.y)*(MONTH(_xlpm.d)=_xlpm.m)), _xlpm.n,_xlfn._xlws.FILTER(_xlpm.net,(YEAR(_xlpm.d)=_xlpm.y)*(MONTH(_xlpm.d)=_xlpm.m)), IFERROR(SUM(_xlpm.n)/SUM(_xlpm.c),""))} | H3: {=_xlfn.LET(_xlpm.y,$A3,_xlpm.m,$B3, _xlpm.d,一覧!$A$2:$A$99999, _xlpm.cnt,一覧!$B$2:$B$99999, _xlpm.net,一覧!$C$2:$C$99999, _xlpm.dc,_xlfn._xlws.FILTER(_xlpm.cnt,(YEAR(_xlpm.d)=_xlpm.y)*(MONTH(_xlpm.d)=_xlpm.m)*(_xlpm.cnt>0)), _xlpm.dn,_xlfn._xlws.FILTER(_xlpm.net,(YEAR(_xlpm.d)=_xlpm.y)*(MONTH(_xlpm.d)=_xlpm.m)*(_xlpm.cnt>0)), _xlpm.unit, _xlpm.dn/_xlpm.dc, IFERROR(MEDIAN(_xlpm.unit),""))} | I3: {=_xlfn.LET(_xlpm.y,$A3,_xlpm.m,$B3, _xlpm.d,一覧!$A$2:$A$99999, _xlpm.cnt,一覧!$B$2:$B$99999, _xlpm.net,一覧!$G$2:$G$99999, _xlpm.c,_xlfn._xlws.FILTER(_xlpm.cnt,(YEAR(_xlpm.d)=_xlpm.y)*(MONTH(_xlpm.d)=_xlpm.m)), _xlpm.n,_xlfn._xlws.FILTER(_xlpm.net,(YEAR(_xlpm.d)=_xlpm.y)*(MONTH(_xlpm.d)=_xlpm.m)), IFERROR(SUM(_xlpm.n)/SUM(_xlpm.c),""))} | J3: {=_xlfn.LET(_xlpm.y,$A3,_xlpm.m,$B3, _xlpm.d,一覧!$A$2:$A$99999, _xlpm.cnt,一覧!$B$2:$B$99999, _xlpm.net,一覧!$G$2:$G$99999, _xlpm.dc,_xlfn._xlws.FILTER(_xlpm.cnt,(YEAR(_xlpm.d)=_xlpm.y)*(MONTH(_xlpm.d)=_xlpm.m)*(_xlpm.cnt>0)), _xlpm.dn,_xlfn._xlws.FILTER(_xlpm.net,(YEAR(_xlpm.d)=_xlpm.y)*(MONTH(_xlpm.d)=_xlpm.m)*(_xlpm.cnt>0)), _xlpm.unit, _xlpm.dn/_xlpm.dc, IFERROR(MEDIAN(_xlpm.unit),""))}
A4: 2025 | B4: 3 | C4: {=_xlfn.LET(_xlpm.y,$A4,_xlpm.m,$B4, _xlpm.d,一覧!$A$2:$A$99999, _xlpm.net,一覧!$C$2:$C$99999, IFERROR(ROWS(_xlfn._xlws.FILTER(_xlpm.d,(YEAR(_xlpm.d)=_xlpm.y)*(MONTH(_xlpm.d)=_xlpm.m)*(_xlpm.net<>""))),0))} -> 15 | D4: {=_xlfn.LET(_xlpm.y,$A4,_xlpm.m,$B4, _xlpm.d,一覧!$A$2:$A$99999, _xlpm.cnt,一覧!$B$2:$B$99999, _xlpm.a,_xlfn._xlws.FILTER(_xlpm.cnt,(YEAR(_xlpm.d)=_xlpm.y)*(MONTH(_xlpm.d)=_xlpm.m)), IFERROR(SUM(_xlpm.a),0))} -> 169 | E4: {=_xlfn.LET(_xlpm.y,$A4,_xlpm.m,$B4, _xlpm.d,一覧!$A$2:$A$99999, _xlpm.net,一覧!$C$2:$C$99999, _xlpm.a,_xlfn._xlws.FILTER(_xlpm.net,(YEAR(_xlpm.d)=_xlpm.y)*(MONTH(_xlpm.d)=_xlpm.m)), IFERROR(SUM(_xlpm.a),0))} -> 75930 | F4: {=_xlfn.LET(_xlpm.y,$A4,_xlpm.m,$B4, _xlpm.d,一覧!$A$2:$A$99999, _xlpm.net,一覧!$G$2:$G$99999, _xlpm.a,_xlfn._xlws.FILTER(_xlpm.net,(YEAR(_xlpm.d)=_xlpm.y)*(MONTH(_xlpm.d)=_xlpm.m)), IFERROR(SUM(_xlpm.a),0))} -> 78554 | G4: {=_xlfn.LET(_xlpm.y,$A4,_xlpm.m,$B4, _xlpm.d,一覧!$A$2:$A$99999, _xlpm.cnt,一覧!$B$2:$B$99999, _xlpm.net,一覧!$C$2:$C$99999, _xlpm.c,_xlfn._xlws.FILTER(_xlpm.cnt,(YEAR(_xlpm.d)=_xlpm.y)*(MONTH(_xlpm.d)=_xlpm.m)), _xlpm.n,_xlfn._xlws.FILTER(_xlpm.net,(YEAR(_xlpm.d)=_xlpm.y)*(MONTH(_xlpm.d)=_xlpm.m)), IFERROR(SUM(_xlpm.n)/SUM(_xlpm.c),""))} -> 449.28994 | H4: {=_xlfn.LET(_xlpm.y,$A4,_xlpm.m,$B4, _xlpm.d,一覧!$A$2:$A$99999, _xlpm.cnt,一覧!$B$2:$B$99999, _xlpm.net,一覧!$C$2:$C$99999, _xlpm.dc,_xlfn._xlws.FILTER(_xlpm.cnt,(YEAR(_xlpm.d)=_xlpm.y)*(MONTH(_xlpm.d)=_xlpm.m)*(_xlpm.cnt>0)), _xlpm.dn,_xlfn._xlws.FILTER(_xlpm.net,(YEAR(_xlpm.d)=_xlpm.y)*(MONTH(_xlpm.d)=_xlpm.m)*(_xlpm.cnt>0)), _xlpm.unit, _xlpm.dn/_xlpm.dc, IFERROR(MEDIAN(_xlpm.unit),""))} -> 447.07692 | I4: {=_xlfn.LET(_xlpm.y,$A4,_xlpm.m,$B4, _xlpm.d,一覧!$A$2:$A$99999, _xlpm.cnt,一覧!$B$2:$B$99999, _xlpm.net,一覧!$G$2:$G$99999, _xlpm.c,_xlfn._xlws.FILTER(_xlpm.cnt,(YEAR(_xlpm.d)=_xlpm.y)*(MONTH(_xlpm.d)=_xlpm.m)), _xlpm.n,_xlfn._xlws.FILTER(_xlpm.net,(YEAR(_xlpm.d)=_xlpm.y)*(MONTH(_xlpm.d)=_xlpm.m)), IFERROR(SUM(_xlpm.n)/SUM(_xlpm.c),""))} -> 464.81657 | J4: {=_xlfn.LET(_xlpm.y,$A4,_xlpm.m,$B4, _xlpm.d,一覧!$A$2:$A$99999, _xlpm.cnt,一覧!$B$2:$B$99999, _xlpm.net,一覧!$G$2:$G$99999, _xlpm.dc,_xlfn._xlws.FILTER(_xlpm.cnt,(YEAR(_xlpm.d)=_xlpm.y)*(MONTH(_xlpm.d)=_xlpm.m)*(_xlpm.cnt>0)), _xlpm.dn,_xlfn._xlws.FILTER(_xlpm.net,(YEAR(_xlpm.d)=_xlpm.y)*(MONTH(_xlpm.d)=_xlpm.m)*(_xlpm.cnt>0)), _xlpm.unit, _xlpm.dn/_xlpm.dc, IFERROR(MEDIAN(_xlpm.unit),""))} -> 458.42857
A5: 2025 | B5: 4 | C5: {=_xlfn.LET(_xlpm.y,$A5,_xlpm.m,$B5, _xlpm.d,一覧!$A$2:$A$99999, _xlpm.net,一覧!$C$2:$C$99999, IFERROR(ROWS(_xlfn._xlws.FILTER(_xlpm.d,(YEAR(_xlpm.d)=_xlpm.y)*(MONTH(_xlpm.d)=_xlpm.m)*(_xlpm.net<>""))),0))} -> 13 | D5: {=_xlfn.LET(_xlpm.y,$A5,_xlpm.m,$B5, _xlpm.d,一覧!$A$2:$A$99999, _xlpm.cnt,一覧!$B$2:$B$99999, _xlpm.a,_xlfn._xlws.FILTER(_xlpm.cnt,(YEAR(_xlpm.d)=_xlpm.y)*(MONTH(_xlpm.d)=_xlpm.m)), IFERROR(SUM(_xlpm.a),0))} -> 213 | E5: {=_xlfn.LET(_xlpm.y,$A5,_xlpm.m,$B5, _xlpm.d,一覧!$A$2:$A$99999, _xlpm.net,一覧!$C$2:$C$99999, _xlpm.a,_xlfn._xlws.FILTER(_xlpm.net,(YEAR(_xlpm.d)=_xlpm.y)*(MONTH(_xlpm.d)=_xlpm.m)), IFERROR(SUM(_xlpm.a),0))} -> 87812 | F5: {=_xlfn.LET(_xlpm.y,$A5,_xlpm.m,$B5, _xlpm.d,一覧!$A$2:$A$99999, _xlpm.net,一覧!$G$2:$G$99999, _xlpm.a,_xlfn._xlws.FILTER(_xlpm.net,(YEAR(_xlpm.d)=_xlpm.y)*(MONTH(_xlpm.d)=_xlpm.m)), IFERROR(SUM(_xlpm.a),0))} -> 114745 | G5: {=_xlfn.LET(_xlpm.y,$A5,_xlpm.m,$B5, _xlpm.d,一覧!$A$2:$A$99999, _xlpm.cnt,一覧!$B$2:$B$99999, _xlpm.net,一覧!$C$2:$C$99999, _xlpm.c,_xlfn._xlws.FILTER(_xlpm.cnt,(YEAR(_xlpm.d)=_xlpm.y)*(MONTH(_xlpm.d)=_xlpm.m)), _xlpm.n,_xlfn._xlws.FILTER(_xlpm.net,(YEAR(_xlpm.d)=_xlpm.y)*(MONTH(_xlpm.d)=_xlpm.m)), IFERROR(SUM(_xlpm.n)/SUM(_xlpm.c),""))} -> 412.26291 | H5: {=_xlfn.LET(_xlpm.y,$A5,_xlpm.m,$B5, _xlpm.d,一覧!$A$2:$A$99999, _xlpm.cnt,一覧!$B$2:$B$99999, _xlpm.net,一覧!$C$2:$C$99999, _xlpm.dc,_xlfn._xlws.FILTER(_xlpm.cnt,(YEAR(_xlpm.d)=_xlpm.y)*(MONTH(_xlpm.d)=_xlpm.m)*(_xlpm.cnt>0)), _xlpm.dn,_xlfn._xlws.FILTER(_xlpm.net,(YEAR(_xlpm.d)=_xlpm.y)*(MONTH(_xlpm.d)=_xlpm.m)*(_xlpm.cnt>0)), _xlpm.unit, _xlpm.dn/_xlpm.dc, IFERROR(MEDIAN(_xlpm.unit),""))} -> 419.34375 | I5: {=_xlfn.LET(_xlpm.y,$A5,_xlpm.m,$B5, _xlpm.d,一覧!$A$2:$A$99999, _xlpm.cnt,一覧!$B$2:$B$99999, _xlpm.net,一覧!$G$2:$G$99999, _xlpm.c,_xlfn._xlws.FILTER(_xlpm.cnt,(YEAR(_xlpm.d)=_xlpm.y)*(MONTH(_xlpm.d)=_xlpm.m)), _xlpm.n,_xlfn._xlws.FILTER(_xlpm.net,(YEAR(_xlpm.d)=_xlpm.y)*(MONTH(_xlpm.d)=_xlpm.m)), IFERROR(SUM(_xlpm.n)/SUM(_xlpm.c),""))} -> 538.70892 | J5: {=_xlfn.LET(_xlpm.y,$A5,_xlpm.m,$B5, _xlpm.d,一覧!$A$2:$A$99999, _xlpm.cnt,一覧!$B$2:$B$99999, _xlpm.net,一覧!$G$2:$G$99999, _xlpm.dc,_xlfn._xlws.FILTER(_xlpm.cnt,(YEAR(_xlpm.d)=_xlpm.y)*(MONTH(_xlpm.d)=_xlpm.m)*(_xlpm.cnt>0)), _xlpm.dn,_xlfn._xlws.FILTER(_xlpm.net,(YEAR(_xlpm.d)=_xlpm.y)*(MONTH(_xlpm.d)=_xlpm.m)*(_xlpm.cnt>0)), _xlpm.unit, _xlpm.dn/_xlpm.dc, IFERROR(MEDIAN(_xlpm.unit),""))} -> 485.57895
A6: 2025 | B6: 5 | C6: {=_xlfn.LET(_xlpm.y,$A6,_xlpm.m,$B6, _xlpm.d,一覧!$A$2:$A$99999, _xlpm.net,一覧!$C$2:$C$99999, IFERROR(ROWS(_xlfn._xlws.FILTER(_xlpm.d,(YEAR(_xlpm.d)=_xlpm.y)*(MONTH(_xlpm.d)=_xlpm.m)*(_xlpm.net<>""))),0))} -> 0 | D6: {=_xlfn.LET(_xlpm.y,$A6,_xlpm.m,$B6, _xlpm.d,一覧!$A$2:$A$99999, _xlpm.cnt,一覧!$B$2:$B$99999, _xlpm.a,_xlfn._xlws.FILTER(_xlpm.cnt,(YEAR(_xlpm.d)=_xlpm.y)*(MONTH(_xlpm.d)=_xlpm.m)), IFERROR(SUM(_xlpm.a),0))} -> 0 | E6: {=_xlfn.LET(_xlpm.y,$A6,_xlpm.m,$B6, _xlpm.d,一覧!$A$2:$A$99999, _xlpm.net,一覧!$C$2:$C$99999, _xlpm.a,_xlfn._xlws.FILTER(_xlpm.net,(YEAR(_xlpm.d)=_xlpm.y)*(MONTH(_xlpm.d)=_xlpm.m)), IFERROR(SUM(_xlpm.a),0))} -> 0 | F6: {=_xlfn.LET(_xlpm.y,$A6,_xlpm.m,$B6, _xlpm.d,一覧!$A$2:$A$99999, _xlpm.net,一覧!$G$2:$G$99999, _xlpm.a,_xlfn._xlws.FILTER(_xlpm.net,(YEAR(_xlpm.d)=_xlpm.y)*(MONTH(_xlpm.d)=_xlpm.m)), IFERROR(SUM(_xlpm.a),0))} -> 0 | G6: {=_xlfn.LET(_xlpm.y,$A6,_xlpm.m,$B6, _xlpm.d,一覧!$A$2:$A$99999, _xlpm.cnt,一覧!$B$2:$B$99999, _xlpm.net,一覧!$C$2:$C$99999, _xlpm.c,_xlfn._xlws.FILTER(_xlpm.cnt,(YEAR(_xlpm.d)=_xlpm.y)*(MONTH(_xlpm.d)=_xlpm.m)), _xlpm.n,_xlfn._xlws.FILTER(_xlpm.net,(YEAR(_xlpm.d)=_xlpm.y)*(MONTH(_xlpm.d)=_xlpm.m)), IFERROR(SUM(_xlpm.n)/SUM(_xlpm.c),""))} | H6: {=_xlfn.LET(_xlpm.y,$A6,_xlpm.m,$B6, _xlpm.d,一覧!$A$2:$A$99999, _xlpm.cnt,一覧!$B$2:$B$99999, _xlpm.net,一覧!$C$2:$C$99999, _xlpm.dc,_xlfn._xlws.FILTER(_xlpm.cnt,(YEAR(_xlpm.d)=_xlpm.y)*(MONTH(_xlpm.d)=_xlpm.m)*(_xlpm.cnt>0)), _xlpm.dn,_xlfn._xlws.FILTER(_xlpm.net,(YEAR(_xlpm.d)=_xlpm.y)*(MONTH(_xlpm.d)=_xlpm.m)*(_xlpm.cnt>0)), _xlpm.unit, _xlpm.dn/_xlpm.dc, IFERROR(MEDIAN(_xlpm.unit),""))} | I6: {=_xlfn.LET(_xlpm.y,$A6,_xlpm.m,$B6, _xlpm.d,一覧!$A$2:$A$99999, _xlpm.cnt,一覧!$B$2:$B$99999, _xlpm.net,一覧!$G$2:$G$99999, _xlpm.c,_xlfn._xlws.FILTER(_xlpm.cnt,(YEAR(_xlpm.d)=_xlpm.y)*(MONTH(_xlpm.d)=_xlpm.m)), _xlpm.n,_xlfn._xlws.FILTER(_xlpm.net,(YEAR(_xlpm.d)=_xlpm.y)*(MONTH(_xlpm.d)=_xlpm.m)), IFERROR(SUM(_xlpm.n)/SUM(_xlpm.c),""))} | J6: {=_xlfn.LET(_xlpm.y,$A6,_xlpm.m,$B6, _xlpm.d,一覧!$A$2:$A$99999, _xlpm.cnt,一覧!$B$2:$B$99999, _xlpm.net,一覧!$G$2:$G$99999, _xlpm.dc,_xlfn._xlws.FILTER(_xlpm.cnt,(YEAR(_xlpm.d)=_xlpm.y)*(MONTH(_xlpm.d)=_xlpm.m)*(_xlpm.cnt>0)), _xlpm.dn,_xlfn._xlws.FILTER(_xlpm.net,(YEAR(_xlpm.d)=_xlpm.y)*(MONTH(_xlpm.d)=_xlpm.m)*(_xlpm.cnt>0)), _xlpm.unit, _xlpm.dn/_xlpm.dc, IFERROR(MEDIAN(_xlpm.unit),""))}
A7: 2025 | B7: 6 | C7: {=_xlfn.LET(_xlpm.y,$A7,_xlpm.m,$B7, _xlpm.d,一覧!$A$2:$A$99999, _xlpm.net,一覧!$C$2:$C$99999, IFERROR(ROWS(_xlfn._xlws.FILTER(_xlpm.d,(YEAR(_xlpm.d)=_xlpm.y)*(MONTH(_xlpm.d)=_xlpm.m)*(_xlpm.net<>""))),0))} -> 12 | D7: {=_xlfn.LET(_xlpm.y,$A7,_xlpm.m,$B7, _xlpm.d,一覧!$A$2:$A$99999, _xlpm.cnt,一覧!$B$2:$B$99999, _xlpm.a,_xlfn._xlws.FILTER(_xlpm.cnt,(YEAR(_xlpm.d)=_xlpm.y)*(MONTH(_xlpm.d)=_xlpm.m)), IFERROR(SUM(_xlpm.a),0))} -> 129 | E7: {=_xlfn.LET(_xlpm.y,$A7,_xlpm.m,$B7, _xlpm.d,一覧!$A$2:$A$99999, _xlpm.net,一覧!$C$2:$C$99999, _xlpm.a,_xlfn._xlws.FILTER(_xlpm.net,(YEAR(_xlpm.d)=_xlpm.y)*(MONTH(_xlpm.d)=_xlpm.m)), IFERROR(SUM(_xlpm.a),0))} -> 63834 | F7: {=_xlfn.LET(_xlpm.y,$A7,_xlpm.m,$B7, _xlpm.d,一覧!$A$2:$A$99999, _xlpm.net,一覧!$G$2:$G$99999, _xlpm.a,_xlfn._xlws.FILTER(_xlpm.net,(YEAR(_xlpm.d)=_xlpm.y)*(MONTH(_xlpm.d)=_xlpm.m)), IFERROR(SUM(_xlpm.a),0))} -> 73522 | G7: {=_xlfn.LET(_xlpm.y,$A7,_xlpm.m,$B7, _xlpm.d,一覧!$A$2:$A$99999, _xlpm.cnt,一覧!$B$2:$B$99999, _xlpm.net,一覧!$C$2:$C$99999, _xlpm.c,_xlfn._xlws.FILTER(_xlpm.cnt,(YEAR(_xlpm.d)=_xlpm.y)*(MONTH(_xlpm.d)=_xlpm.m)), _xlpm.n,_xlfn._xlws.FILTER(_xlpm.net,(YEAR(_xlpm.d)=_xlpm.y)*(MONTH(_xlpm.d)=_xlpm.m)), IFERROR(SUM(_xlpm.n)/SUM(_xlpm.c),""))} -> 494.83721 | H7: {=_xlfn.LET(_xlpm.y,$A7,_xlpm.m,$B7, _xlpm.d,一覧!$A$2:$A$99999, _xlpm.cnt,一覧!$B$2:$B$99999, _xlpm.net,一覧!$C$2:$C$99999, _xlpm.dc,_xlfn._xlws.FILTER(_xlpm.cnt,(YEAR(_xlpm.d)=_xlpm.y)*(MONTH(_xlpm.d)=_xlpm.m)*(_xlpm.cnt>0)), _xlpm.dn,_xlfn._xlws.FILTER(_xlpm.net,(YEAR(_xlpm.d)=_xlpm.y)*(MONTH(_xlpm.d)=_xlpm.m)*(_xlpm.cnt>0)), _xlpm.unit, _xlpm.dn/_xlpm.dc, IFERROR(MEDIAN(_xlpm.unit),""))} -> 502.44167 | I7: {=_xlfn.LET(_xlpm.y,$A7,_xlpm.m,$B7, _xlpm.d,一覧!$A$2:$A$99999, _xlpm.cnt,一覧!$B$2:$B$99999, _xlpm.net,一覧!$G$2:$G$99999, _xlpm.c,_xlfn._xlws.FILTER(_xlpm.cnt,(YEAR(_xlpm.d)=_xlpm.y)*(MONTH(_xlpm.d)=_xlpm.m)), _xlpm.n,_xlfn._xlws.FILTER(_xlpm.net,(YEAR(_xlpm.d)=_xlpm.y)*(MONTH(_xlpm.d)=_xlpm.m)), IFERROR(SUM(_xlpm.n)/SUM(_xlpm.c),""))} -> 569.93798 | J7: {=_xlfn.LET(_xlpm.y,$A7,_xlpm.m,$B7, _xlpm.d,一覧!$A$2:$A$99999, _xlpm.cnt,一覧!$B$2:$B$99999, _xlpm.net,一覧!$G$2:$G$99999, _xlpm.dc,_xlfn._xlws.FILTER(_xlpm.cnt,(YEAR(_xlpm.d)=_xlpm.y)*(MONTH(_xlpm.d)=_xlpm.m)*(_xlpm.cnt>0)), _xlpm.dn,_xlfn._xlws.FILTER(_xlpm.net,(YEAR(_xlpm.d)=_xlpm.y)*(MONTH(_xlpm.d)=_xlpm.m)*(_xlpm.cnt>0)), _xlpm.unit, _xlpm.dn/_xlpm.dc, IFERROR(MEDIAN(_xlpm.unit),""))} -> 554.58333
A8: 2025 | B8: 7 | C8: {=_xlfn.LET(_xlpm.y,$A8,_xlpm.m,$B8, _xlpm.d,一覧!$A$2:$A$99999, _xlpm.net,一覧!$C$2:$C$99999, IFERROR(ROWS(_xlfn._xlws.FILTER(_xlpm.d,(YEAR(_xlpm.d)=_xlpm.y)*(MONTH(_xlpm.d)=_xlpm.m)*(_xlpm.net<>""))),0))} -> 14 | D8: {=_xlfn.LET(_xlpm.y,$A8,_xlpm.m,$B8, _xlpm.d,一覧!$A$2:$A$99999, _xlpm.cnt,一覧!$B$2:$B$99999, _xlpm.a,_xlfn._xlws.FILTER(_xlpm.cnt,(YEAR(_xlpm.d)=_xlpm.y)*(MONTH(_xlpm.d)=_xlpm.m)), IFERROR(SUM(_xlpm.a),0))} -> 271 | E8: {=_xlfn.LET(_xlpm.y,$A8,_xlpm.m,$B8, _xlpm.d,一覧!$A$2:$A$99999, _xlpm.net,一覧!$C$2:$C$99999, _xlpm.a,_xlfn._xlws.FILTER(_xlpm.net,(YEAR(_xlpm.d)=_xlpm.y)*(MONTH(_xlpm.d)=_xlpm.m)), IFERROR(SUM(_xlpm.a),0))} -> 117275 | F8: {=_xlfn.LET(_xlpm.y,$A8,_xlpm.m,$B8, _xlpm.d,一覧!$A$2:$A$99999, _xlpm.net,一覧!$G$2:$G$99999, _xlpm.a,_xlfn._xlws.FILTER(_xlpm.net,(YEAR(_xlpm.d)=_xlpm.y)*(MONTH(_xlpm.d)=_xlpm.m)), IFERROR(SUM(_xlpm.a),0))} -> 152841 | G8: {=_xlfn.LET(_xlpm.y,$A8,_xlpm.m,$B8, _xlpm.d,一覧!$A$2:$A$99999, _xlpm.cnt,一覧!$B$2:$B$99999, _xlpm.net,一覧!$C$2:$C$99999, _xlpm.c,_xlfn._xlws.FILTER(_xlpm.cnt,(YEAR(_xlpm.d)=_xlpm.y)*(MONTH(_xlpm.d)=_xlpm.m)), _xlpm.n,_xlfn._xlws.FILTER(_xlpm.net,(YEAR(_xlpm.d)=_xlpm.y)*(MONTH(_xlpm.d)=_xlpm.m)), IFERROR(SUM(_xlpm.n)/SUM(_xlpm.c),""))} -> 432.74908 | H8: {=_xlfn.LET(_xlpm.y,$A8,_xlpm.m,$B8, _xlpm.d,一覧!$A$2:$A$99999, _xlpm.cnt,一覧!$B$2:$B$99999, _xlpm.net,一覧!$C$2:$C$99999, _xlpm.dc,_xlfn._xlws.FILTER(_xlpm.cnt,(YEAR(_xlpm.d)=_xlpm.y)*(MONTH(_xlpm.d)=_xlpm.m)*(_xlpm.cnt>0)), _xlpm.dn,_xlfn._xlws.FILTER(_xlpm.net,(YEAR(_xlpm.d)=_xlpm.y)*(MONTH(_xlpm.d)=_xlpm.m)*(_xlpm.cnt>0)), _xlpm.unit, _xlpm.dn/_xlpm.dc, IFERROR(MEDIAN(_xlpm.unit),""))} -> 437.01471 | I8: {=_xlfn.LET(_xlpm.y,$A8,_xlpm.m,$B8, _xlpm.d,一覧!$A$2:$A$99999, _xlpm.cnt,一覧!$B$2:$B$99999, _xlpm.net,一覧!$G$2:$G$99999, _xlpm.c,_xlfn._xlws.FILTER(_xlpm.cnt,(YEAR(_xlpm.d)=_xlpm.y)*(MONTH(_xlpm.d)=_xlpm.m)), _xlpm.n,_xlfn._xlws.FILTER(_xlpm.net,(YEAR(_xlpm.d)=_xlpm.y)*(MONTH(_xlpm.d)=_xlpm.m)), IFERROR(SUM(_xlpm.n)/SUM(_xlpm.c),""))} -> 563.98893 | J8: {=_xlfn.LET(_xlpm.y,$A8,_xlpm.m,$B8, _xlpm.d,一覧!$A$2:$A$99999, _xlpm.cnt,一覧!$B$2:$B$99999, _xlpm.net,一覧!$G$2:$G$99999, _xlpm.dc,_xlfn._xlws.FILTER(_xlpm.cnt,(YEAR(_xlpm.d)=_xlpm.y)*(MONTH(_xlpm.d)=_xlpm.m)*(_xlpm.cnt>0)), _xlpm.dn,_xlfn._xlws.FILTER(_xlpm.net,(YEAR(_xlpm.d)=_xlpm.y)*(MONTH(_xlpm.d)=_xlpm.m)*(_xlpm.cnt>0)), _xlpm.unit, _xlpm.dn/_xlpm.dc, IFERROR(MEDIAN(_xlpm.unit),""))} -> 503.58266
A9: 2025 | B9: 8 | C9: {=_xlfn.LET(_xlpm.y,$A9,_xlpm.m,$B9, _xlpm.d,一覧!$A$2:$A$99999, _xlpm.net,一覧!$C$2:$C$99999, IFERROR(ROWS(_xlfn._xlws.FILTER(_xlpm.d,(YEAR(_xlpm.d)=_xlpm.y)*(MONTH(_xlpm.d)=_xlpm.m)*(_xlpm.net<>""))),0))} -> 15 | D9: {=_xlfn.LET(_xlpm.y,$A9,_xlpm.m,$B9, _xlpm.d,一覧!$A$2:$A$99999, _xlpm.cnt,一覧!$B$2:$B$99999, _xlpm.a,_xlfn._xlws.FILTER(_xlpm.cnt,(YEAR(_xlpm.d)=_xlpm.y)*(MONTH(_xlpm.d)=_xlpm.m)), IFERROR(SUM(_xlpm.a),0))} -> 347 | E9: {=_xlfn.LET(_xlpm.y,$A9,_xlpm.m,$B9, _xlpm.d,一覧!$A$2:$A$99999, _xlpm.net,一覧!$C$2:$C$99999, _xlpm.a,_xlfn._xlws.FILTER(_xlpm.net,(YEAR(_xlpm.d)=_xlpm.y)*(MONTH(_xlpm.d)=_xlpm.m)), IFERROR(SUM(_xlpm.a),0))} -> 158006 | F9: {=_xlfn.LET(_xlpm.y,$A9,_xlpm.m,$B9, _xlpm.d,一覧!$A$2:$A$99999, _xlpm.net,一覧!$G$2:$G$99999, _xlpm.a,_xlfn._xlws.FILTER(_xlpm.net,(YEAR(_xlpm.d)=_xlpm.y)*(MONTH(_xlpm.d)=_xlpm.m)), IFERROR(SUM(_xlpm.a),0))} -> 205910 | G9: {=_xlfn.LET(_xlpm.y,$A9,_xlpm.m,$B9, _xlpm.d,一覧!$A$2:$A$99999, _xlpm.cnt,一覧!$B$2:$B$99999, _xlpm.net,一覧!$C$2:$C$99999, _xlpm.c,_xlfn._xlws.FILTER(_xlpm.cnt,(YEAR(_xlpm.d)=_xlpm.y)*(MONTH(_xlpm.d)=_xlpm.m)), _xlpm.n,_xlfn._xlws.FILTER(_xlpm.net,(YEAR(_xlpm.d)=_xlpm.y)*(MONTH(_xlpm.d)=_xlpm.m)), IFERROR(SUM(_xlpm.n)/SUM(_xlpm.c),""))} -> 455.3487 | H9: {=_xlfn.LET(_xlpm.y,$A9,_xlpm.m,$B9, _xlpm.d,一覧!$A$2:$A$99999, _xlpm.cnt,一覧!$B$2:$B$99999, _xlpm.net,一覧!$C$2:$C$99999, _xlpm.dc,_xlfn._xlws.FILTER(_xlpm.cnt,(YEAR(_xlpm.d)=_xlpm.y)*(MONTH(_xlpm.d)=_xlpm.m)*(_xlpm.cnt>0)), _xlpm.dn,_xlfn._xlws.FILTER(_xlpm.net,(YEAR(_xlpm.d)=_xlpm.y)*(MONTH(_xlpm.d)=_xlpm.m)*(_xlpm.cnt>0)), _xlpm.unit, _xlpm.dn/_xlpm.dc, IFERROR(MEDIAN(_xlpm.unit),""))} -> 468.2 | I9: {=_xlfn.LET(_xlpm.y,$A9,_xlpm.m,$B9, _xlpm.d,一覧!$A$2:$A$99999, _xlpm.cnt,一覧!$B$2:$B$99999, _xlpm.net,一覧!$G$2:$G$99999, _xlpm.c,_xlfn._xlws.FILTER(_xlpm.cnt,(YEAR(_xlpm.d)=_xlpm.y)*(MONTH(_xlpm.d)=_xlpm.m)), _xlpm.n,_xlfn._xlws.FILTER(_xlpm.net,(YEAR(_xlpm.d)=_xlpm.y)*(MONTH(_xlpm.d)=_xlpm.m)), IFERROR(SUM(_xlpm.n)/SUM(_xlpm.c),""))} -> 593.40058 | J9: {=_xlfn.LET(_xlpm.y,$A9,_xlpm.m,$B9, _xlpm.d,一覧!$A$2:$A$99999, _xlpm.cnt,一覧!$B$2:$B$99999, _xlpm.net,一覧!$G$2:$G$99999, _xlpm.dc,_xlfn._xlws.FILTER(_xlpm.cnt,(YEAR(_xlpm.d)=_xlpm.y)*(MONTH(_xlpm.d)=_xlpm.m)*(_xlpm.cnt>0)), _xlpm.dn,_xlfn._xlws.FILTER(_xlpm.net,(YEAR(_xlpm.d)=_xlpm.y)*(MONTH(_xlpm.d)=_xlpm.m)*(_xlpm.cnt>0)), _xlpm.unit, _xlpm.dn/_xlpm.dc, IFERROR(MEDIAN(_xlpm.unit),""))} -> 642.9
A10: 2025 | B10: 9 | C10: {=_xlfn.LET(_xlpm.y,$A10,_xlpm.m,$B10, _xlpm.d,一覧!$A$2:$A$99999, _xlpm.net,一覧!$C$2:$C$99999, IFERROR(ROWS(_xlfn._xlws.FILTER(_xlpm.d,(YEAR(_xlpm.d)=_xlpm.y)*(MONTH(_xlpm.d)=_xlpm.m)*(_xlpm.net<>""))),0))} -> 3 | D10: {=_xlfn.LET(_xlpm.y,$A10,_xlpm.m,$B10, _xlpm.d,一覧!$A$2:$A$99999, _xlpm.cnt,一覧!$B$2:$B$99999, _xlpm.a,_xlfn._xlws.FILTER(_xlpm.cnt,(YEAR(_xlpm.d)=_xlpm.y)*(MONTH(_xlpm.d)=_xlpm.m)), IFERROR(SUM(_xlpm.a),0))} -> 51 | E10: {=_xlfn.LET(_xlpm.y,$A10,_xlpm.m,$B10, _xlpm.d,一覧!$A$2:$A$99999, _xlpm.net,一覧!$C$2:$C$99999, _xlpm.a,_xlfn._xlws.FILTER(_xlpm.net,(YEAR(_xlpm.d)=_xlpm.y)*(MONTH(_xlpm.d)=_xlpm.m)), IFERROR(SUM(_xlpm.a),0))} -> 25146 | F10: {=_xlfn.LET(_xlpm.y,$A10,_xlpm.m,$B10, _xlpm.d,一覧!$A$2:$A$99999, _xlpm.net,一覧!$G$2:$G$99999, _xlpm.a,_xlfn._xlws.FILTER(_xlpm.net,(YEAR(_xlpm.d)=_xlpm.y)*(MONTH(_xlpm.d)=_xlpm.m)), IFERROR(SUM(_xlpm.a),0))} -> 27256 | G10: {=_xlfn.LET(_xlpm.y,$A10,_xlpm.m,$B10, _xlpm.d,一覧!$A$2:$A$99999, _xlpm.cnt,一覧!$B$2:$B$99999, _xlpm.net,一覧!$C$2:$C$99999, _xlpm.c,_xlfn._xlws.FILTER(_xlpm.cnt,(YEAR(_xlpm.d)=_xlpm.y)*(MONTH(_xlpm.d)=_xlpm.m)), _xlpm.n,_xlfn._xlws.FILTER(_xlpm.net,(YEAR(_xlpm.d)=_xlpm.y)*(MONTH(_xlpm.d)=_xlpm.m)), IFERROR(SUM(_xlpm.n)/SUM(_xlpm.c),""))} -> 493.05882 | H10: {=_xlfn.LET(_xlpm.y,$A10,_xlpm.m,$B10, _xlpm.d,一覧!$A$2:$A$99999, _xlpm.cnt,一覧!$B$2:$B$99999, _xlpm.net,一覧!$C$2:$C$99999, _xlpm.dc,_xlfn._xlws.FILTER(_xlpm.cnt,(YEAR(_xlpm.d)=_xlpm.y)*(MONTH(_xlpm.d)=_xlpm.m)*(_xlpm.cnt>0)), _xlpm.dn,_xlfn._xlws.FILTER(_xlpm.net,(YEAR(_xlpm.d)=_xlpm.y)*(MONTH(_xlpm.d)=_xlpm.m)*(_xlpm.cnt>0)), _xlpm.unit, _xlpm.dn/_xlpm.dc, IFERROR(MEDIAN(_xlpm.unit),""))} -> 447.625 | I10: {=_xlfn.LET(_xlpm.y,$A10,_xlpm.m,$B10, _xlpm.d,一覧!$A$2:$A$99999, _xlpm.cnt,一覧!$B$2:$B$99999, _xlpm.net,一覧!$G$2:$G$99999, _xlpm.c,_xlfn._xlws.FILTER(_xlpm.cnt,(YEAR(_xlpm.d)=_xlpm.y)*(MONTH(_xlpm.d)=_xlpm.m)), _xlpm.n,_xlfn._xlws.FILTER(_xlpm.net,(YEAR(_xlpm.d)=_xlpm.y)*(MONTH(_xlpm.d)=_xlpm.m)), IFERROR(SUM(_xlpm.n)/SUM(_xlpm.c),""))} -> 534.43137 | J10: {=_xlfn.LET(_xlpm.y,$A10,_xlpm.m,$B10, _xlpm.d,一覧!$A$2:$A$99999, _xlpm.cnt,一覧!$B$2:$B$99999, _xlpm.net,一覧!$G$2:$G$99999, _xlpm.dc,_xlfn._xlws.FILTER(_xlpm.cnt,(YEAR(_xlpm.d)=_xlpm.y)*(MONTH(_xlpm.d)=_xlpm.m)*(_xlpm.cnt>0)), _xlpm.dn,_xlfn._xlws.FILTER(_xlpm.net,(YEAR(_xlpm.d)=_xlpm.y)*(MONTH(_xlpm.d)=_xlpm.m)*(_xlpm.cnt>0)), _xlpm.unit, _xlpm.dn/_xlpm.dc, IFERROR(MEDIAN(_xlpm.unit),""))} -> 523.25
A11: 2025 | B11: 10 | C11: {=_xlfn.LET(_xlpm.y,$A11,_xlpm.m,$B11, _xlpm.d,一覧!$A$2:$A$99999, _xlpm.net,一覧!$C$2:$C$99999, IFERROR(ROWS(_xlfn._xlws.FILTER(_xlpm.d,(YEAR(_xlpm.d)=_xlpm.y)*(MONTH(_xlpm.d)=_xlpm.m)*(_xlpm.net<>""))),0))} -> 11 | D11: {=_xlfn.LET(_xlpm.y,$A11,_xlpm.m,$B11, _xlpm.d,一覧!$A$2:$A$99999, _xlpm.cnt,一覧!$B$2:$B$99999, _xlpm.a,_xlfn._xlws.FILTER(_xlpm.cnt,(YEAR(_xlpm.d)=_xlpm.y)*(MONTH(_xlpm.d)=_xlpm.m)), IFERROR(SUM(_xlpm.a),0))} -> 257 | E11: {=_xlfn.LET(_xlpm.y,$A11,_xlpm.m,$B11, _xlpm.d,一覧!$A$2:$A$99999, _xlpm.net,一覧!$C$2:$C$99999, _xlpm.a,_xlfn._xlws.FILTER(_xlpm.net,(YEAR(_xlpm.d)=_xlpm.y)*(MONTH(_xlpm.d)=_xlpm.m)), IFERROR(SUM(_xlpm.a),0))} -> 115281 | F11: {=_xlfn.LET(_xlpm.y,$A11,_xlpm.m,$B11, _xlpm.d,一覧!$A$2:$A$99999, _xlpm.net,一覧!$G$2:$G$99999, _xlpm.a,_xlfn._xlws.FILTER(_xlpm.net,(YEAR(_xlpm.d)=_xlpm.y)*(MONTH(_xlpm.d)=_xlpm.m)), IFERROR(SUM(_xlpm.a),0))} -> 139307 | G11: {=_xlfn.LET(_xlpm.y,$A11,_xlpm.m,$B11, _xlpm.d,一覧!$A$2:$A$99999, _xlpm.cnt,一覧!$B$2:$B$99999, _xlpm.net,一覧!$C$2:$C$99999, _xlpm.c,_xlfn._xlws.FILTER(_xlpm.cnt,(YEAR(_xlpm.d)=_xlpm.y)*(MONTH(_xlpm.d)=_xlpm.m)), _xlpm.n,_xlfn._xlws.FILTER(_xlpm.net,(YEAR(_xlpm.d)=_xlpm.y)*(MONTH(_xlpm.d)=_xlpm.m)), IFERROR(SUM(_xlpm.n)/SUM(_xlpm.c),""))} -> 448.5642 | H11: {=_xlfn.LET(_xlpm.y,$A11,_xlpm.m,$B11, _xlpm.d,一覧!$A$2:$A$99999, _xlpm.cnt,一覧!$B$2:$B$99999, _xlpm.net,一覧!$C$2:$C$99999, _xlpm.dc,_xlfn._xlws.FILTER(_xlpm.cnt,(YEAR(_xlpm.d)=_xlpm.y)*(MONTH(_xlpm.d)=_xlpm.m)*(_xlpm.cnt>0)), _xlpm.dn,_xlfn._xlws.FILTER(_xlpm.net,(YEAR(_xlpm.d)=_xlpm.y)*(MONTH(_xlpm.d)=_xlpm.m)*(_xlpm.cnt>0)), _xlpm.unit, _xlpm.dn/_xlpm.dc, IFERROR(MEDIAN(_xlpm.unit),""))} -> 434.65 | I11: {=_xlfn.LET(_xlpm.y,$A11,_xlpm.m,$B11, _xlpm.d,一覧!$A$2:$A$99999, _xlpm.cnt,一覧!$B$2:$B$99999, _xlpm.net,一覧!$G$2:$G$99999, _xlpm.c,_xlfn._xlws.FILTER(_xlpm.cnt,(YEAR(_xlpm.d)=_xlpm.y)*(MONTH(_xlpm.d)=_xlpm.m)), _xlpm.n,_xlfn._xlws.FILTER(_xlpm.net,(YEAR(_xlpm.d)=_xlpm.y)*(MONTH(_xlpm.d)=_xlpm.m)), IFERROR(SUM(_xlpm.n)/SUM(_xlpm.c),""))} -> 542.05058 | J11: {=_xlfn.LET(_xlpm.y,$A11,_xlpm.m,$B11, _xlpm.d,一覧!$A$2:$A$99999, _xlpm.cnt,一覧!$B$2:$B$99999, _xlpm.net,一覧!$G$2:$G$99999, _xlpm.dc,_xlfn._xlws.FILTER(_xlpm.cnt,(YEAR(_xlpm.d)=_xlpm.y)*(MONTH(_xlpm.d)=_xlpm.m)*(_xlpm.cnt>0)), _xlpm.dn,_xlfn._xlws.FILTER(_xlpm.net,(YEAR(_xlpm.d)=_xlpm.y)*(MONTH(_xlpm.d)=_xlpm.m)*(_xlpm.cnt>0)), _xlpm.unit, _xlpm.dn/_xlpm.dc, IFERROR(MEDIAN(_xlpm.unit),""))} -> 567.33333
A12: 2025 | B12: 11 | C12: {=_xlfn.LET(_xlpm.y,$A12,_xlpm.m,$B12, _xlpm.d,一覧!$A$2:$A$99999, _xlpm.net,一覧!$C$2:$C$99999, IFERROR(ROWS(_xlfn._xlws.FILTER(_xlpm.d,(YEAR(_xlpm.d)=_xlpm.y)*(MONTH(_xlpm.d)=_xlpm.m)*(_xlpm.net<>""))),0))} -> 1 | D12: {=_xlfn.LET(_xlpm.y,$A12,_xlpm.m,$B12, _xlpm.d,一覧!$A$2:$A$99999, _xlpm.cnt,一覧!$B$2:$B$99999, _xlpm.a,_xlfn._xlws.FILTER(_xlpm.cnt,(YEAR(_xlpm.d)=_xlpm.y)*(MONTH(_xlpm.d)=_xlpm.m)), IFERROR(SUM(_xlpm.a),0))} -> 1 | E12: {=_xlfn.LET(_xlpm.y,$A12,_xlpm.m,$B12, _xlpm.d,一覧!$A$2:$A$99999, _xlpm.net,一覧!$C$2:$C$99999, _xlpm.a,_xlfn._xlws.FILTER(_xlpm.net,(YEAR(_xlpm.d)=_xlpm.y)*(MONTH(_xlpm.d)=_xlpm.m)), IFERROR(SUM(_xlpm.a),0))} -> 320 | F12: {=_xlfn.LET(_xlpm.y,$A12,_xlpm.m,$B12, _xlpm.d,一覧!$A$2:$A$99999, _xlpm.net,一覧!$G$2:$G$99999, _xlpm.a,_xlfn._xlws.FILTER(_xlpm.net,(YEAR(_xlpm.d)=_xlpm.y)*(MONTH(_xlpm.d)=_xlpm.m)), IFERROR(SUM(_xlpm.a),0))} -> 320 | G12: {=_xlfn.LET(_xlpm.y,$A12,_xlpm.m,$B12, _xlpm.d,一覧!$A$2:$A$99999, _xlpm.cnt,一覧!$B$2:$B$99999, _xlpm.net,一覧!$C$2:$C$99999, _xlpm.c,_xlfn._xlws.FILTER(_xlpm.cnt,(YEAR(_xlpm.d)=_xlpm.y)*(MONTH(_xlpm.d)=_xlpm.m)), _xlpm.n,_xlfn._xlws.FILTER(_xlpm.net,(YEAR(_xlpm.d)=_xlpm.y)*(MONTH(_xlpm.d)=_xlpm.m)), IFERROR(SUM(_xlpm.n)/SUM(_xlpm.c),""))} -> 320 | H12: {=_xlfn.LET(_xlpm.y,$A12,_xlpm.m,$B12, _xlpm.d,一覧!$A$2:$A$99999, _xlpm.cnt,一覧!$B$2:$B$99999, _xlpm.net,一覧!$C$2:$C$99999, _xlpm.dc,_xlfn._xlws.FILTER(_xlpm.cnt,(YEAR(_xlpm.d)=_xlpm.y)*(MONTH(_xlpm.d)=_xlpm.m)*(_xlpm.cnt>0)), _xlpm.dn,_xlfn._xlws.FILTER(_xlpm.net,(YEAR(_xlpm.d)=_xlpm.y)*(MONTH(_xlpm.d)=_xlpm.m)*(_xlpm.cnt>0)), _xlpm.unit, _xlpm.dn/_xlpm.dc, IFERROR(MEDIAN(_xlpm.unit),""))} -> 320 | I12: {=_xlfn.LET(_xlpm.y,$A12,_xlpm.m,$B12, _xlpm.d,一覧!$A$2:$A$99999, _xlpm.cnt,一覧!$B$2:$B$99999, _xlpm.net,一覧!$G$2:$G$99999, _xlpm.c,_xlfn._xlws.FILTER(_xlpm.cnt,(YEAR(_xlpm.d)=_xlpm.y)*(MONTH(_xlpm.d)=_xlpm.m)), _xlpm.n,_xlfn._xlws.FILTER(_xlpm.net,(YEAR(_xlpm.d)=_xlpm.y)*(MONTH(_xlpm.d)=_xlpm.m)), IFERROR(SUM(_xlpm.n)/SUM(_xlpm.c),""))} -> 320 | J12: {=_xlfn.LET(_xlpm.y,$A12,_xlpm.m,$B12, _xlpm.d,一覧!$A$2:$A$99999, _xlpm.cnt,一覧!$B$2:$B$99999, _xlpm.net,一覧!$G$2:$G$99999, _xlpm.dc,_xlfn._xlws.FILTER(_xlpm.cnt,(YEAR(_xlpm.d)=_xlpm.y)*(MONTH(_xlpm.d)=_xlpm.m)*(_xlpm.cnt>0)), _xlpm.dn,_xlfn._xlws.FILTER(_xlpm.net,(YEAR(_xlpm.d)=_xlpm.y)*(MONTH(_xlpm.d)=_xlpm.m)*(_xlpm.cnt>0)), _xlpm.unit, _xlpm.dn/_xlpm.dc, IFERROR(MEDIAN(_xlpm.unit),""))} -> 320
A13: 2025 | B13: 12 | C13: {=_xlfn.LET(_xlpm.y,$A13,_xlpm.m,$B13, _xlpm.d,一覧!$A$2:$A$99999, _xlpm.net,一覧!$C$2:$C$99999, IFERROR(ROWS(_xlfn._xlws.FILTER(_xlpm.d,(YEAR(_xlpm.d)=_xlpm.y)*(MONTH(_xlpm.d)=_xlpm.m)*(_xlpm.net<>""))),0))} -> 12 | D13: {=_xlfn.LET(_xlpm.y,$A13,_xlpm.m,$B13, _xlpm.d,一覧!$A$2:$A$99999, _xlpm.cnt,一覧!$B$2:$B$99999, _xlpm.a,_xlfn._xlws.FILTER(_xlpm.cnt,(YEAR(_xlpm.d)=_xlpm.y)*(MONTH(_xlpm.d)=_xlpm.m)), IFERROR(SUM(_xlpm.a),0))} -> 292 | E13: {=_xlfn.LET(_xlpm.y,$A13,_xlpm.m,$B13, _xlpm.d,一覧!$A$2:$A$99999, _xlpm.net,一覧!$C$2:$C$99999, _xlpm.a,_xlfn._xlws.FILTER(_xlpm.net,(YEAR(_xlpm.d)=_xlpm.y)*(MONTH(_xlpm.d)=_xlpm.m)), IFERROR(SUM(_xlpm.a),0))} -> 144485 | F13: {=_xlfn.LET(_xlpm.y,$A13,_xlpm.m,$B13, _xlpm.d,一覧!$A$2:$A$99999, _xlpm.net,一覧!$G$2:$G$99999, _xlpm.a,_xlfn._xlws.FILTER(_xlpm.net,(YEAR(_xlpm.d)=_xlpm.y)*(MONTH(_xlpm.d)=_xlpm.m)), IFERROR(SUM(_xlpm.a),0))} -> 171676 | G13: {=_xlfn.LET(_xlpm.y,$A13,_xlpm.m,$B13, _xlpm.d,一覧!$A$2:$A$99999, _xlpm.cnt,一覧!$B$2:$B$99999, _xlpm.net,一覧!$C$2:$C$99999, _xlpm.c,_xlfn._xlws.FILTER(_xlpm.cnt,(YEAR(_xlpm.d)=_xlpm.y)*(MONTH(_xlpm.d)=_xlpm.m)), _xlpm.n,_xlfn._xlws.FILTER(_xlpm.net,(YEAR(_xlpm.d)=_xlpm.y)*(MONTH(_xlpm.d)=_xlpm.m)), IFERROR(SUM(_xlpm.n)/SUM(_xlpm.c),""))} -> 494.81164 | H13: {=_xlfn.LET(_xlpm.y,$A13,_xlpm.m,$B13, _xlpm.d,一覧!$A$2:$A$99999, _xlpm.cnt,一覧!$B$2:$B$99999, _xlpm.net,一覧!$C$2:$C$99999, _xlpm.dc,_xlfn._xlws.FILTER(_xlpm.cnt,(YEAR(_xlpm.d)=_xlpm.y)*(MONTH(_xlpm.d)=_xlpm.m)*(_xlpm.cnt>0)), _xlpm.dn,_xlfn._xlws.FILTER(_xlpm.net,(YEAR(_xlpm.d)=_xlpm.y)*(MONTH(_xlpm.d)=_xlpm.m)*(_xlpm.cnt>0)), _xlpm.unit, _xlpm.dn/_xlpm.dc, IFERROR(MEDIAN(_xlpm.unit),""))} -> 474.29605 | I13: {=_xlfn.LET(_xlpm.y,$A13,_xlpm.m,$B13, _xlpm.d,一覧!$A$2:$A$99999, _xlpm.cnt,一覧!$B$2:$B$99999, _xlpm.net,一覧!$G$2:$G$99999, _xlpm.c,_xlfn._xlws.FILTER(_xlpm.cnt,(YEAR(_xlpm.d)=_xlpm.y)*(MONTH(_xlpm.d)=_xlpm.m)), _xlpm.n,_xlfn._xlws.FILTER(_xlpm.net,(YEAR(_xlpm.d)=_xlpm.y)*(MONTH(_xlpm.d)=_xlpm.m)), IFERROR(SUM(_xlpm.n)/SUM(_xlpm.c),""))} -> 587.93151 | J13: {=_xlfn.LET(_xlpm.y,$A13,_xlpm.m,$B13, _xlpm.d,一覧!$A$2:$A$99999, _xlpm.cnt,一覧!$B$2:$B$99999, _xlpm.net,一覧!$G$2:$G$99999, _xlpm.dc,_xlfn._xlws.FILTER(_xlpm.cnt,(YEAR(_xlpm.d)=_xlpm.y)*(MONTH(_xlpm.d)=_xlpm.m)*(_xlpm.cnt>0)), _xlpm.dn,_xlfn._xlws.FILTER(_xlpm.net,(YEAR(_xlpm.d)=_xlpm.y)*(MONTH(_xlpm.d)=_xlpm.m)*(_xlpm.cnt>0)), _xlpm.unit, _xlpm.dn/_xlpm.dc, IFERROR(MEDIAN(_xlpm.unit),""))} -> 562.62083
... A25: 2026 | B25: 12 | C25: {=_xlfn.LET(_xlpm.y,$A25,_xlpm.m,$B25, _xlpm.d,一覧!$A$2:$A$99999, _xlpm.net,一覧!$C$2:$C$99999, IFERROR(ROWS(_xlfn._xlws.FILTER(_xlpm.d,(YEAR(_xlpm.d)=_xlpm.y)*(MONTH(_xlpm.d)=_xlpm.m)*(_xlpm.net<>""))),0))} -> 0 | D25: {=_xlfn.LET(_xlpm.y,$A25,_xlpm.m,$B25, _xlpm.d,一覧!$A$2:$A$99999, _xlpm.cnt,一覧!$B$2:$B$99999, _xlpm.a,_xlfn._xlws.FILTER(_xlpm.cnt,(YEAR(_xlpm.d)=_xlpm.y)*(MONTH(_xlpm.d)=_xlpm.m)), IFERROR(SUM(_xlpm.a),0))} -> 0 | E25: {=_xlfn.LET(_xlpm.y,$A25,_xlpm.m,$B25, _xlpm.d,一覧!$A$2:$A$99999, _xlpm.net,一覧!$C$2:$C$99999, _xlpm.a,_xlfn._xlws.FILTER(_xlpm.net,(YEAR(_xlpm.d)=_xlpm.y)*(MONTH(_xlpm.d)=_xlpm.m)), IFERROR(SUM(_xlpm.a),0))} -> 0 | F25: {=_xlfn.LET(_xlpm.y,$A25,_xlpm.m,$B25, _xlpm.d,一覧!$A$2:$A$99999, _xlpm.net,一覧!$G$2:$G$99999, _xlpm.a,_xlfn._xlws.FILTER(_xlpm.net,(YEAR(_xlpm.d)=_xlpm.y)*(MONTH(_xlpm.d)=_xlpm.m)), IFERROR(SUM(_xlpm.a),0))} -> 0 | G25: {=_xlfn.LET(_xlpm.y,$A25,_xlpm.m,$B25, _xlpm.d,一覧!$A$2:$A$99999, _xlpm.cnt,一覧!$B$2:$B$99999, _xlpm.net,一覧!$C$2:$C$99999, _xlpm.c,_xlfn._xlws.FILTER(_xlpm.cnt,(YEAR(_xlpm.d)=_xlpm.y)*(MONTH(_xlpm.d)=_xlpm.m)), _xlpm.n,_xlfn._xlws.FILTER(_xlpm.net,(YEAR(_xlpm.d)=_xlpm.y)*(MONTH(_xlpm.d)=_xlpm.m)), IFERROR(SUM(_xlpm.n)/SUM(_xlpm.c),""))} | H25: {=_xlfn.LET(_xlpm.y,$A25,_xlpm.m,$B25, _xlpm.d,一覧!$A$2:$A$99999, _xlpm.cnt,一覧!$B$2:$B$99999, _xlpm.net,一覧!$C$2:$C$99999, _xlpm.dc,_xlfn._xlws.FILTER(_xlpm.cnt,(YEAR(_xlpm.d)=_xlpm.y)*(MONTH(_xlpm.d)=_xlpm.m)*(_xlpm.cnt>0)), _xlpm.dn,_xlfn._xlws.FILTER(_xlpm.net,(YEAR(_xlpm.d)=_xlpm.y)*(MONTH(_xlpm.d)=_xlpm.m)*(_xlpm.cnt>0)), _xlpm.unit, _xlpm.dn/_xlpm.dc, IFERROR(MEDIAN(_xlpm.unit),""))} | I25: {=_xlfn.LET(_xlpm.y,$A25,_xlpm.m,$B25, _xlpm.d,一覧!$A$2:$A$99999, _xlpm.cnt,一覧!$B$2:$B$99999, _xlpm.net,一覧!$G$2:$G$99999, _xlpm.c,_xlfn._xlws.FILTER(_xlpm.cnt,(YEAR(_xlpm.d)=_xlpm.y)*(MONTH(_xlpm.d)=_xlpm.m)), _xlpm.n,_xlfn._xlws.FILTER(_xlpm.net,(YEAR(_xlpm.d)=_xlpm.y)*(MONTH(_xlpm.d)=_xlpm.m)), IFERROR(SUM(_xlpm.n)/SUM(_xlpm.c),""))} | J25: {=_xlfn.LET(_xlpm.y,$A25,_xlpm.m,$B25, _xlpm.d,一覧!$A$2:$A$99999, _xlpm.cnt,一覧!$B$2:$B$99999, _xlpm.net,一覧!$G$2:$G$99999, _xlpm.dc,_xlfn._xlws.FILTER(_xlpm.cnt,(YEAR(_xlpm.d)=_xlpm.y)*(MONTH(_xlpm.d)=_xlpm.m)*(_xlpm.cnt>0)), _xlpm.dn,_xlfn._xlws.FILTER(_xlpm.net,(YEAR(_xlpm.d)=_xlpm.y)*(MONTH(_xlpm.d)=_xlpm.m)*(_xlpm.cnt>0)), _xlpm.unit, _xlpm.dn/_xlpm.dc, IFERROR(MEDIAN(_xlpm.unit),""))}
